Workbook

Sheet BOM
A1: WYVERN-E 3.0 — Master Bill of Materials (complete project)
A2: Prices re-verified 2026-06-21 (Adafruit/Apogee/CSRocketry live; Amazon=list) · Pi5 4GB $130 · booster = F52T reload (ARC-legal F) ×12 + 4 casings · Teensy 4.0 runs real-time hardware PWM (servos via PCA9685) · wind tunnel + TVC balance on 'GSE & Test Equip' sheet · *PJRC/JollyLogic/McMaster = noted exceptions
A4: 1. Flight Computer, Sensors & Control
A5: Item | B5: Storefront | C5: Part # / Spec | D5: Link | E5: Stock | F5: Qty | G5: Unit ($) | H5: Line ($)
A6: Raspberry Pi 5 (4 GB) | B6: Adafruit | C6: ID 5812 | D6: Buy ▸ | E6: In stock | F6: 1 | G6: 130 | H6: =F6*G6 -> 130
A7: Official Pi 5 Active Cooler | B7: Adafruit | C7: ID 5815 | D7: Buy ▸ | E7: In stock | F7: 1 | G7: 13.5 | H7: =F7*G7 -> 13.5
A8: Teensy 4.0 — real-time TVC PWM / control coprocessor | B8: PJRC* | C8: Teensy 4.0 | D8: Buy ▸ | E8: In stock | F8: 1 | G8: 19.95 | H8: =F8*G8 -> 19.95
A9: Camera Module 3 | B9: Adafruit | C9: ID 5657 | D9: Buy ▸ | E9: In stock | F9: 1 | G9: 29.25 | H9: =F9*G9 -> 29.25
A10: Pi 5 FPC camera cable 22→15-pin 200mm | B10: Adafruit | C10: ID 5818 | D10: Buy ▸ | E10: In stock | F10: 1 | G10: 2.7 | H10: =F10*G10 -> 2.7
A11: BNO085 9-DOF IMU (gimbal / FC / nose) | B11: Adafruit | C11: ID 4754 | D11: Buy ▸ | E11: In stock | F11: 3 | G11: 24.95 | H11: =F11*G11 -> 74.85
A12: LSM6DSO32 ±32 g accel/gyro | B12: Adafruit | C12: ID 4692 | D12: Buy ▸ | E12: In stock | F12: 1 | G12: 11.95 | H12: =F12*G12 -> 11.95
A13: LIS2MDL magnetometer | B13: Adafruit | C13: ID 4488 | D13: Buy ▸ | E13: In stock | F13: 1 | G13: 4.95 | H13: =F13*G13 -> 4.95
A14: BMP280 barometer | B14: Adafruit | C14: ID 2651 | D14: Buy ▸ | E14: In stock | F14: 1 | G14: 9.95 | H14: =F14*G14 -> 9.95
A15: BME688 gas/T/P/RH | B15: Adafruit | C15: ID 5046 | D15: Buy ▸ | E15: In stock | F15: 1 | G15: 22.5 | H15: =F15*G15 -> 22.5
A16: microSD SPI breakout (video + log) | B16: Adafruit | C16: ID 4682 | D16: Buy ▸ | E16: In stock | F16: 2 | G16: 3.95 | H16: =F16*G16 -> 7.9
A17: SanDisk 32 GB microSD (video/log/boot) | B17: Amazon | C17: B08GY9NYRM | D17: Buy ▸ | E17: In stock | F17: 3 | G17: 9 | H17: =F17*G17 -> 27
... A21: Arduino Nano (3-pk) — bench / stand DAQ | B21: Amazon | C21: LAFVIN B07G99NNXL | D21: Buy ▸ | E21: In stock | F21: 1 | G21: 15.99 | H21: =F21*G21 -> 15.99
A22: Subtotal | H22: =SUM(H6:H21) -> 398.39
A24: 2. Power System (USB-C rechargeable)
A25: Item | B25: Storefront | C25: Part # / Spec | D25: Link | E25: Stock | F25: Qty | G25: Unit ($) | H25: Line ($)
A26: 3S Li-Po 11.1 V 3000 mAh w/ XT60 | B26: Amazon | C26: E-flite B013TKVHPO | D26: Buy ▸ | E26: In stock | F26: 1 | G26: 33.99 | H26: =F26*G26 -> 33.99
A27: IP2368 USB-C PD buck-boost charge board | B27: Amazon | C27: B0DP6CGN33 | D27: Buy ▸ | E27: In stock | F27: 1 | G27: 16 | H27: =F27*G27 -> 16
A28: DROK 9-36V→5V 6A buck (Pi 5 rail) | B28: Amazon | C28: DROK B01NALDSJ0 | D28: Buy ▸ | E28: In stock | F28: 1 | G28: 10.99 | H28: =F28*G28 -> 10.99
A29: DROK 6.5-36V→1.2-32V 4.5A buck (6 V servo rail) | B29: Amazon | C29: DROK B07FL6PBZF | D29: Buy ▸ | E29: In stock | F29: 1 | G29: 13.99 | H29: =F29*G29 -> 13.99
A30: Master switch + fuse + distribution | B30: Adafruit | C30: ID 3218 | D30: Buy ▸ | E30: In stock | F30: 1 | G30: 8 | H30: =F30*G30 -> 8
A31: Subtotal | H31: =SUM(H26:H30) -> 82.97
A33: 3. Recovery & Pyro
A34: Item | B34: Storefront | C34: Part # / Spec | D34: Link | E34: Stock | F34: Qty | G34: Unit ($) | H34: Line ($)
A35: MissileWorks RRC3+ dual-deploy + 2nd-stage | B35: Apogee | C35: id 2048 | D35: Buy ▸ | E35: In stock | F35: 1 | G35: 79.95 | H35: =F35*G35 -> 79.95
A36: Jolly Logic Altimeter 2 (backup record) | B36: Jolly Logic* | C36: AltimeterTwo | D36: Buy ▸ | E36: In stock | F36: 1 | G36: 79.95 | H36: =F36*G36 -> 79.95
A37: Estes Rip Stop 24" nylon parachute | B37: Estes | C37: Rip Stop 24 | D37: Buy ▸ | E37: In stock | F37: 1 | G37: 10.25 | H37: =F37*G37 -> 10.25
A38: 1/8" Kevlar shock cord (4500#, 30 ft) | B38: Apogee | C38: Kevlar 30ft | D38: Buy ▸ | E38: In stock | F38: 1 | G38: 12 | H38: =F38*G38 -> 12
A39: Firewire initiators (6/pk) | B39: Apogee | C39: id 2449 | D39: Buy ▸ | E39: In stock | F39: 1 | G39: 14 | H39: =F39*G39 -> 14
A40: Ejection canister caps (2 pk) | B40: Apogee | C40: E-Match Mate | D40: Buy ▸ | E40: In stock | F40: 1 | G40: 7.95 | H40: =F40*G40 -> 7.95
A41: FFFFg black powder (per-flight lot) | B41: Apogee | C41: Ejection Sys | D41: Buy ▸ | E41: In stock | F41: 1 | G41: 4 | H41: =F41*G41 -> 4
A42: Subtotal | H42: =SUM(H35:H41) -> 208.1
A44: 4. TVC — System A (tri-solenoid; Teensy hardware PWM)
A45: Item | B45: Storefront | C45: Part # / Spec | D45: Link | E45: Stock | F45: Qty | G45: Unit ($) | H45: Line ($)
A46: 50 N 12 V solenoid (gimbal actuator) | B46: Amazon | C46: TOMSHIELE B0CTG4X882 | D46: Buy ▸ | E46: In stock | F46: 3 | G46: 10.99 | H46: =F46*G46 -> 32.97
A47: IRF520 MOSFET driver (4-ct) — gated by Teensy FlexPWM | B47: Amazon | C47: HiLetgo B01I1J14MO | D47: Buy ▸ | E47: In stock | F47: 1 | G47: 6.99 | H47: =F47*G47 -> 6.99
...

Sheet Summary
A1: WYVERN-E 3.0 — Cost Summary
A3: Category | B3: Subtotal ($)
A4: 1. Flight Computer, Sensors & Control | B4: =BOM!H22 -> 398.39
A5: 2. Power System (USB-C rechargeable) | B5: =BOM!H31 -> 82.97
A6: 3. Recovery & Pyro | B6: =BOM!H42 -> 208.1
A7: 4. TVC — System A (tri-solenoid; Teensy hardware PWM) | B7: =BOM!H50 -> 70.95
A8: 5. TVC — System B (servo-gimbal; PCA9685 hardware PWM) | B8: =BOM!H57 -> 91.92
A9: 6. Propulsion (reloads; booster ≥10 + 3+ casings per spec) | B9: =BOM!H66 -> 1081.61
A10: 7. Airframe & Mechanism (filament, qty = kg, unit = $/kg) | B10: =BOM!H74 -> 27.072
A11: 8. Harness, Connectors & Assembly Consumables | B11: =BOM!H88 -> 113.78
A12: 9. Ground Support — launch & static stand | B12: =BOM!H98 -> 223.472
A13: 10. Tools — one-time, specialized | B13: =BOM!H108 -> 222.94
A14: GRAND TOTAL | B14: =SUM(B4:B13) -> 2521.204
A16: + GSE & Test Equip (separate sheet) | B16: ='GSE & Test Equip'!H46 -> 594.9

Sheet Purchase Links
A1: WYVERN-E 3.0 — Full Purchase Links (master)
A3: Item | B3: Storefront | C3: Part # / Spec | D3: Full URL
A4: Raspberry Pi 5 (4 GB) | B4: Adafruit | C4: ID 5812 | D4: https://www.adafruit.com/product/5812
A5: Official Pi 5 Active Cooler | B5: Adafruit | C5: ID 5815 | D5: https://www.adafruit.com/product/5815
A6: Teensy 4.0 — real-time TVC PWM / control coprocessor | B6: PJRC* | C6: Teensy 4.0 | D6: https://www.pjrc.com/store/teensy40.html
A7: Camera Module 3 | B7: Adafruit | C7: ID 5657 | D7: https://www.adafruit.com/product/5657
A8: Pi 5 FPC camera cable 22→15-pin 200mm | B8: Adafruit | C8: ID 5818 | D8: https://www.adafruit.com/product/5818
A9: BNO085 9-DOF IMU (gimbal / FC / nose) | B9: Adafruit | C9: ID 4754 | D9: https://www.adafruit.com/product/4754
A10: LSM6DSO32 ±32 g accel/gyro | B10: Adafruit | C10: ID 4692 | D10: https://www.adafruit.com/product/4692
A11: LIS2MDL magnetometer | B11: Adafruit | C11: ID 4488 | D11: https://www.adafruit.com/product/4488
A12: BMP280 barometer | B12: Adafruit | C12: ID 2651 | D12: https://www.adafruit.com/product/2651
A13: BME688 gas/T/P/RH | B13: Adafruit | C13: ID 5046 | D13: https://www.adafruit.com/product/5046
A14: microSD SPI breakout (video + log) | B14: Adafruit | C14: ID 4682 | D14: https://www.adafruit.com/product/4682
... A69: iCrimp SN-2549 crimper + 1550-pc JST/Dupont kit | B69: Amazon | C69: B08ZRT496D | D69: https://www.amazon.com/dp/B08ZRT496D

Sheet GSE & Test Equip
A1: WYVERN-E 3.0 — GSE & Test Equipment (Hofferth wind tunnel · TVC balance)
A2: Fan = pick ONE: AC Infinity A8 (recommended, 724 CFM, force-measurement upgrade) OR Delta PFB1212UHE (compact 120 mm alt). See WYVERN_E3_GSE_TestEquipment.md for the trade study + print manifest. Amazon prices est.
A4: A. Wind Tunnel — Fan & Drive (RECOMMENDED: 8" duct fan, best for force measurement)
A5: Item | B5: Storefront | C5: Part # / Spec | D5: Link | E5: Need | F5: Qty | G5: Unit ($) | H5: Line ($)
A6: AC Infinity Cloudline A8 8" inline fan — 724 CFM, 42 dB, EC + 10-speed ctrl | B6: Amazon | C6: Cloudline A8 | D6: Buy ▸ | E6: Recommended | F6: 1 | G6: 89 | H6: =F6*G6 -> 89
A7: Rubber duct coupler + hose clamps (diffuser → A8) | B7: Amazon | C7: duct coupler | D7: Buy ▸ | E7: Recommended | F7: 1 | G7: 12 | H7: =F7*G7 -> 12
A8: Subtotal | H8: =SUM(H6:H7) -> 101
A10: A2. Wind Tunnel — Fan alternative (compact 120 mm high-static-pressure)
A11: Item | B11: Storefront | C11: Part # / Spec | D11: Link | E11: Need | F11: Qty | G11: Unit ($) | H11: Line ($)
A12: Delta PFB1212UHE 120mm fan — 253 CFM, 351 Pa, 48 W, 66 dB | B12: Amazon | C12: B0036WG1ES | D12: Buy ▸ | E12: Alt | F12: 1 | G12: 39 | H12: =F12*G12 -> 39
A13: 12 V 10 A supply (PFB1212UHE only) | B13: Amazon | C13: Bringsmart B07F8PTQSY | D13: Buy ▸ | E13: Alt | F13: 1 | G13: 18.99 | H13: =F13*G13 -> 18.99
A14: PWM DC speed controller 12-40 V 10 A (PFB only) | B14: Amazon | C14: RioRand B007TH4EN6 | D14: Buy ▸ | E14: Alt | F14: 1 | G14: 11.99 | H14: =F14*G14 -> 11.99
A15: Subtotal | H15: =SUM(H12:H14) -> 69.98
A17: B. Wind Tunnel — Flow Conditioning & Assembly
A18: Item | B18: Storefront | C18: Part # / Spec | D18: Link | E18: Need | F18: Qty | G18: Unit ($) | H18: Line ($)
A19: 40-mesh SS woven screen (15 cm) — flow conditioning | B19: Amazon | C19: Inoxia B074XFJWWV | D19: Buy ▸ | E19: Req'd | F19: 2 | G19: 11 | H19: =F19*G19 -> 22
A20: 80-mesh SS woven screen (15 cm) — flow conditioning | B20: Amazon | C20: Inoxia B074XGBD45 | D20: Buy ▸ | E20: Req'd | F20: 1 | G20: 11 | H20: =F20*G20 -> 11
A21: Heat-set insert assortment M2-M6 (M5 junction rings, M2.5 window tabs) | B21: Amazon | C21: HANGLIFE B0CTGVDLKH | D21: Buy ▸ | E21: Req'd | F21: 1 | G21: 13.99 | H21: =F21*G21 -> 13.99
A22: Neodymium discs 6×2 mm (Gridfinity test-article bases, 100 pc) | B22: Amazon | C22: B096RFNYD9 | D22: Buy ▸ | E22: Req'd | F22: 1 | G22: 8.99 | H22: =F22*G22 -> 8.99
A23: Neodymium discs 10×3 mm (test-section floor) | B23: Amazon | C23: 10×3 mm | D23: Buy ▸ | E23: Req'd | F23: 1 | G23: 9.99 | H23: =F23*G23 -> 9.99
A24: 2 mm OD brass tube (smoke-rake exit ports) | B24: Amazon | C24: brass tube | D24: Buy ▸ | E24: Optional | F24: 1 | G24: 9.99 | H24: =F24*G24 -> 9.99
A25: 3 mm acrylic windows (80×130) or SendCutSend preset cart | B25: SendCutSend* | C25: preset cart | D25: Buy ▸ | E25: Req'd | F25: 1 | G25: 29 | H25: =F25*G25 -> 29
A26: O-rings ASTM A568-160 / -275 (inter-module seal) | B26: Amazon | C26: A568 | D26: Buy ▸ | E26: Optional | F26: 1 | G26: 12 | H26: =F26*G26 -> 12
A27: Subtotal | H27: =SUM(H19:H26) -> 116.96
A29: C. Wind Tunnel — Smoke/Light Visualization (optional)
A30: Item | B30: Storefront | C30: Part # / Spec | D30: Link | E30: Need | F30: Qty | G30: Unit ($) | H30: Line ($)
A31: ¼" Loc-Line coolant hose kit (smoke rake feed) | B31: Amazon | C31: LP-40413 B002QG4F8Y | D31: Buy ▸ | E31: Optional | F31: 1 | G31: 14.99 | H31: =F31*G31 -> 14.99
A32: VG/PG smoke juice | B32: Amazon | C32: VG+PG | D32: Buy ▸ | E32: Optional | F32: 1 | G32: 15 | H32: =F32*G32 -> 15
A33: 520 nm green line laser (light sheet) | B33: Amazon | C33: OXLasers B0BY15NCY8 | D33: Buy ▸ | E33: Optional | F33: 1 | G33: 39 | H33: =F33*G33 -> 39
A34: RGBWW LED flood (Aputure MC) | B34: Amazon | C34: Aputure MC | D34: Buy ▸ | E34: Optional | F34: 1 | G34: 90 | H34: =F34*G34 -> 90
A35: Handheld VG/PG fogger (MicroFogger / Ulanzi Filmog) | B35: see Hofferth list | C35: fogger | D35: Buy ▸ | E35: Optional | F35: 1 | G35: 100 | H35: =F35*G35 -> 100
A36: Subtotal | H36: =SUM(H31:H35) -> 258.99
A38: D. TVC Thrust-Vector Balance (ground test — both A & B)
A39: Item | B39: Storefront | C39: Part # / Spec | D39: Link | E39: Need | F39: Qty | G39: Unit ($) | H39: Line ($)
A40: 10 kg load cell + HX711 — axial (Z) thrust | B40: Amazon | C40: NOYITO B07CN1VDC4 | D40: Buy ▸ | E40: Req'd | F40: 1 | G40: 10.99 | H40: =F40*G40 -> 10.99
A41: 1 kg load cell + HX711 — lateral (X,Y) side-force | B41: Amazon | C41: NOYITO B07BGRDKG5 | D41: Buy ▸ | E41: Req'd | F41: 2 | G41: 10.99 | H41: =F41*G41 -> 21.98
A42: Steel blast-deflector plate (~150×150×3 mm) | B42: McMaster* | C42: mild steel | D42: Buy ▸ | E42: Req'd | F42: 1 | G42: 15 | H42: =F42*G42 -> 15
A43: DAQ — Arduino Nano (already in master BOM; reused here) | B43: — | C43: see BOM §1 | D43: — | E43: Have | F43: 0 | G43: 0 | H43: =F43*G43 -> 0
A44: Subtotal | H44: =SUM(H40:H43) -> 47.97
A46: GSE & TEST EQUIP TOTAL (fan = pick one; separate from vehicle BOM) | H46: =H8+H15+H27+H36+H44 -> 594.9
