Workbook

Sheet BOM
A1: WYVERN-E - Master Bill of Materials
A2: Amazon to-buy reconciled to actual cart (28 items, $609.72) + kept 2S-LiPo battery; Adafruit = cart minus PCA9548/STEMMA-300 (in Acquired). Real /dp/ ASINs. 2026-07 | 2026-08: section 9 (Hofferth wind tunnel) STRUCK - wind tunnel removed from program scope.
A4: 1. Flight Computer & Sensors
A5: Item | B5: Storefront | C5: Part # / Spec | D5: Link | E5: Note | F5: Qty | G5: Unit ($) | H5: Line ($)
A6: Raspberry Pi Pico 2 W (pre-soldered header) - flight FC + spare | B6: Amazon | C6: B0DP54FWX1 | D6: Buy | E6: in cart | F6: 2 | G6: 16.31 | H6: =F6*G6
A7: BNO085 9-DOF IMU (gimbal/body/recovery + spare, GRV) | B7: Adafruit | C7: PID 4754 | D7: Buy | E7: in Adafruit cart | F7: 4 | G7: 24.95 | H7: =F7*G7
A8: BMP388 precision barometric pressure/altitude sensor | B8: Adafruit | C8: PID 3966 | D8: Buy | E8: in Adafruit cart | F8: 2 | G8: 9.95 | H8: =F8*G8
A9: i3 4K Thumb Action Camera (64G card, self-contained ~36 g) | B9: Amazon | C9: B0DDSH1W1N | D9: Buy | E9: in cart (64G variant) | F9: 1 | G9: 73.99 | H9: =F9*G9
A10: Liaoan USB-A/USB-C 3.0 OTG adapter set (6 pc) | B10: Amazon | C10: B0FQBPZPKF | D10: Buy | E10: in cart; data/flash + microSD | F10: 1 | G10: 16.99 | H10: =F10*G10
A11: Subtotal | H11: =SUM(H6:H10)
A13: 2. Power (2S LiPo + UBEC) - kept per design, not in this Amazon cart
A14: Item | B14: Storefront | C14: Part # / Spec | D14: Link | E14: Note | F14: Qty | G14: Unit ($) | H14: Line ($)
A15: Zeee 2S 7.4 V 450 mAh LiPo (4-pk) - light flight pack | B15: Amazon | C15: Zeee B0DGQ5HHMY | D15: Buy | E15: ~30 g; kept (not in this cart) | F15: 1 | G15: 15.99 | H15: =F15*G15
A16: Hobbywing 5 V/6 V 3 A UBEC / BEC (set 5 V -> Pico + servos) | B16: Amazon | C16: Hobbywing B008ZNWOYY | D16: Buy | E16: kept (not in this cart) | F16: 1 | G16: 8.99 | H16: =F16*G16
A17: HTRC B3 2S-3S LiPo balance charger | B17: Amazon | C17: HTRC B08HN5DZ5Y | D17: Buy | E17: kept (not in this cart) | F17: 1 | G17: 13.99 | H17: =F17*G17
A18: Decoupling kit: 1000 uF + 100 uF low-ESR caps + SS34 Schottky | B18: Amazon | C18: low-ESR cap + SS34 | D18: Buy | E18: no verified ASIN | F18: 1 | G18: 9.99 | H18: =F18*G18
A19: 100 kohm / 62 kohm 1% resistor pack (GP26 battery ADC divider) | B19: Amazon | C19: 1% metal-film | D19: Buy | E19: no verified ASIN | F19: 1 | G19: 6.99 | H19: =F19*G19
A20: Small slide arming switch (rocket) | B20: Amazon | C20: SPDT slide switch | D20: Buy | F20: 2 | G20: 0.95 | H20: =F20*G20
A21: Subtotal | H21: =SUM(H15:H20)
A23: 3. TVC - flight (servo, 2-axis gimbal)
A24: Item | B24: Storefront | C24: Part # / Spec | D24: Link | E24: Note | F24: Qty | G24: Unit ($) | H24: Line ($)
A25: EMAX ES08MA II metal-gear analog micro servo (4-pack) | B25: Amazon | C25: B0DN1G3P2M | D25: Buy | E25: in cart, qty 2 (8 servos: flight + spares) | F25: 2 | G25: 37.99 | H25: =F25*G25
A26: XIKE MR105-2RS ball bearings (gimbal, 10-pk) | B26: Amazon | C26: B09DJY425B | D26: Buy | E26: in cart | F26: 2 | G26: 6.99 | H26: =F26*G26
A27: uxcell M2 15 mm linkage rod-end ball joint (4 PCS) | B27: Amazon | C27: B07Q2V3R61 | D27: Buy | E27: in cart | F27: 2 | G27: 12.99 | H27: =F27*G27
A28: Honbay 300 mm servo extension leads (10-pk) | B28: Amazon | C28: B01LA9YDEI | D28: Buy | E28: in cart | F28: 1 | G28: 6.99 | H28: =F28*G28
A29: Subtotal | H29: =SUM(H25:H28)
A31: 4. Recovery (motor ejection via bypass tube)
A32: Item | B32: Storefront | C32: Part # / Spec | D32: Link | E32: Note | F32: Qty | G32: Unit ($) | H32: Line ($)
A33: Estes 24 in rip-stop nylon parachute (FLIGHT canopy - CHUTE_D=0.6096 m in all sims) | B33: Estes | C33: 24in chute | D33: Buy | E33: 2026-08b: switched 18 in -> 24 in. Descent 6.7 -> 5.0 m/s. | F33: 4 | G33: 10.25 | H33: =F33*G33
A34: Aramid (Kevlar) shock cord - 19 ft | B34: Estes | C34: Aramid 19ft | D34: Buy | F34: 1 | G34: 10 | H34: =F34*G34
A35: Estes recovery wadding (72 sheets) | B35: Estes | C35: Recovery wadding | D35: Buy | F35: 2 | G35: 5.99 | H35: =F35*G35
A36: Bypass gas tube + twin sealed bulkheads (printed PC-FR) | B36: In-house | C36: PC-FR (printed) | D36: Buy | E36: printed in-house | F36: 1 | G36: 0 | H36: =F36*G36
A37: Subtotal | H37: =SUM(H33:H36)
A39: 5. Propulsion (Estes motors + launch system)
A40: Item | B40: Storefront | C40: Part # / Spec | D40: Link | E40: Note | F40: Qty | G40: Unit ($) | H40: Line ($)
A41: Estes F15-4 2-ct (flight; 4 s delay + ejection = recovery) | B41: Estes | C41: F15-4 (2-ct) | D41: Buy | E41: 4 motors | F41: 2 | G41: 33.99 | H41: =F41*G41
A42: Estes F15-0 2-ct (ground stands; 0-delay plugged) | B42: Estes | C42: F15-0 (2-ct) | D42: Buy | E42: Static thrust curves + MTVC + servo TVC on the balance (jetvane dropped). | F42: 5 | G42: 33.99 | H42: =F42*G42
A43: Estes E16-4 2-ct (stand commissioning/calibration) | B43: Estes | C43: E16-4 (2-ct) | D43: Buy | E43: Stand commissioning, 2 firings per stand (Gate 5). NOT in the current cart. | F43: 3 | G43: 33.33 | H43: =F43*G43
A44: Estes large engine plugs (40 ct) - plug F15-0 for ground | B44: Estes | C44: Engine plugs 40ct | D44: Buy | E44: Static thrust curves + MTVC + servo TVC on the balance (jetvane dropped). | F44: 1 | G44: 7.49 | H44: =F44*G44
A45: Estes STARTech starters (igniters) | B45: Estes | C45: STARTech | D45: Buy | E45: 6 per pack; ~15 firings planned. Cart has 1 pack - short. | F45: 4 | G45: 6.99 | H45: =F45*G45
...

Sheet Already Acquired
A1: Already Acquired (in master BOM, excluded from to-buy)
A3: Item | B3: Storefront | C3: Part # / Spec | D3: Link | E3: Note | F3: Qty | G3: Paid ea ($) | H3: Line ($)
A4: Bambu Black PETG-CF (materials-test coupons) - 2 kg | B4: Bambu Lab | C4: PETG-CF | D4: Link | F4: 2 | G4: 12.795 | H4: =F4*G4
A5: Bambu White PLA - 1 kg | B5: Bambu Lab | C5: PLA | D5: Link | F5: 1 | G5: 19.99 | H5: =F5*G5
A6: Bambu Black PLA - 1 kg | B6: Bambu Lab | C6: PLA | D6: Link | F6: 1 | G6: 19.99 | H6: =F6*G6
A7: TOMSHIELE 25x11 mm 12 V electromagnet (5 kg) - magnetic TVC (RQ1) | B7: Amazon | C7: TOMSHIELE 25x11 12V | D7: Link | E7: uxcell same spec if OOS | F7: 3 | G7: 9 | H7: =F7*G7
A8: Neodymium disc magnet 30 mm x 3 mm N52 - magnetic TVC | B8: Amazon | C8: 30x3 N52 | D8: Link | E8: CMS/DIYMAG | F8: 1 | G8: 25 | H8: =F8*G8
A9: IRF520 MOSFET (pack of 10) - solenoid driver | B9: Amazon | C9: IRF520 (10pk) | D9: Link | F9: 1 | G9: 7 | H9: =F9*G9
A10: 1N4007 flyback diode (pack of 100) - solenoid driver | B10: Amazon | C10: 1N4007 (100pk) | D10: Link | F10: 1 | G10: 6 | H10: =F10*G10
A11: Arduino Nano - solenoid-rig bench DAQ | B11: Amazon | C11: Nano (clone OK) | D11: Link | E11: bench testing | F11: 1 | G11: 16 | H11: =F11*G11
A12: 12 V 2 A wall adapter (5.5x2.1 mm barrel) - solenoid rig | B12: Amazon | C12: 12V 2A PSU | D12: Link | F12: 1 | G12: 12 | H12: =F12*G12
A13: Breadboard + jumper wires (M-M / M-F / F-F) | B13: Amazon | C13: breadboard+jumpers | D13: Link | F13: 1 | G13: 15 | H13: =F13*G13
A14: J-B Weld Original twin-tube epoxy | B14: Amazon | C14: J-B Weld Original | D14: Link | E14: NOT KwikWeld | F14: 1 | G14: 21 | H14: =F14*G14
A15: Super Lube 21030 PTFE grease (ball/socket lube) | B15: Amazon | C15: Super Lube 21030 | D15: Link | F15: 1 | G15: 11 | H15: =F15*G15
A16: uni USB-C microSD card reader | B16: Amazon | C16: USB-C SD reader | D16: Link | E16: price est. | F16: 1 | G16: 10 | H16: =F16*G16
A17: 32 GB microSD card (flight log + video) | B17: Amazon | C17: microSD 32GB | D17: Link | E17: price est. | F17: 2 | G17: 9 | H17: =F17*G17
A18: Adafruit BME688 temp/humidity/pressure/gas (STEMMA QT) | B18: Adafruit | C18: PID 5046 | D18: Link | E18: price est. | F18: 2 | G18: 22.5 | H18: =F18*G18
A19: Mechatronics MS1238E12B1-6-FHR 120 mm high-static fan | B19: DigiKey | C19: MS1238E12B1-6-FHR | D19: Link | E19: price est. | F19: 1 | G19: 40 | H19: =F19*G19
A20: Neodymium magnet, mag-through-diameter, 1/8 in x 3/16 in OD | B20: McMaster-Carr | C20: 5862K415 | D20: Link | E20: magnetic TVC | F20: 4 | G20: 1.6 | H20: =F20*G20
A21: AIRTAK suction electromagnet 30x22 mm DC12V 100N (10 kg) | B21: Amazon | C21: AIRTAK 30x22 12V | D21: Link | E21: alt electromagnet | F21: 3 | G21: 11.6 | H21: =F21*G21
A22: MECCANIXITY 301 SS foil roll 0.1 x 20 mm x 1 m (shim stock) | B22: Amazon | C22: 301 SS foil | D22: Link | E22: flexure/shim | F22: 1 | G22: 9 | H22: =F22*G22
A23: Adafruit TMAG5273 (A1) 3D Hall-effect magnetometer (STEMMA QT) | B23: Adafruit | C23: PID 6489 | D23: Link | E23: magnetic-gimbal position sensing | F23: 1 | G23: 6 | H23: =F23*G23
A24: Adafruit VL53L4CD Time-of-Flight sensor (owned; removed from design) | B24: Adafruit | C24: PID 5396 | D24: Link | E24: not used in design | F24: 6 | G24: 15 | H24: =F24*G24
A25: Adafruit PCA9548 8-ch I2C multiplexer | B25: Adafruit | C25: PID 5626 | D25: Link | E25: owned - kept in Acquired | F25: 1 | G25: 7 | H25: =F25*G25
A26: STEMMA QT JST-SH 4-pin cable, 300 mm | B26: Adafruit | C26: PID 5384 | D26: Link | E26: owned - kept in Acquired | F26: 6 | G26: 1.25 | H26: =F26*G26
A27: Total already paid | H27: =SUM(H4:H26)

Sheet Summary
A1: WYVERN-E - BOM Summary
A3: 1. Flight Computer & Sensors | B3: =BOM!H11
A4: 2. Power (2S LiPo + UBEC) - kept per design, not in this Amazon cart | B4: =BOM!H21
A5: 3. TVC - flight (servo, 2-axis gimbal) | B5: =BOM!H29
A6: 4. Recovery (motor ejection via bypass tube) | B6: =BOM!H37
A7: 5. Propulsion (Estes motors + launch system) | B7: =BOM!H47
A8: 6. Airframe filament (PLA primary + PETG-CF owned) | B8: =BOM!H56
A9: 7. Harness, connectors, prototyping & assembly | B9: =BOM!H84
A10: 8. Ground test - TVC balance + static stand (load cells + DAQ) | B10: =BOM!H94
A12: Gross to-buy total | B12: =BOM!H96
A13: Less: reimbursed (launch controller) | B13: =-43.99
A14: NET OUT-OF-POCKET (still to buy) | B14: =BOM!H98
A16: Already acquired (owned, not in to-buy) | B16: ='Already Acquired'!H27
A17: Total program spend (net to-buy + already acquired) | B17: =B14+B16
